<?xml version="1.0" ?>
<!-- =================================================================================== -->
<!-- |    This document was autogenerated by xacro from robo.urdf.xacro                | -->
<!-- |    EDITING THIS FILE BY HAND IS NOT RECOMMENDED                                 | -->
<!-- =================================================================================== -->
<robot name="robogardener">
  <!-- 11.5cm diameter -->
  <!-- 19.5cm left-to-right -->
  <!-- 6cm rod height -->
  <!-- kg -->
  <!-- Main chassis link -->
  <link name="base_link">
    <visual>
      <origin rpy="0 0 0" xyz="0 0 0.03"/>
      <geometry>
        <box size="0.37 0.195 0.03"/>
      </geometry>
      <material name="blue"/>
    </visual>
    <collision>
      <origin rpy="0 0 0" xyz="0 0 0.03"/>
      <geometry>
        <box size="0.37 0.195 0.03"/>
      </geometry>
    </collision>
    <inertial>
      <origin xyz="0 0 0.03"/>
      <mass value="2.0"/>
      <inertia ixx="0.0064875" ixy="0" ixz="0" iyy="0.022966666666666666" iyz="0" izz="0.029154166666666665"/>
    </inertial>
  </link>
  <!-- All wheels are FIXED to chassis (mechanically linked) -->
  <!-- Front Left Wheel -->
  <link name="left_f_wheel">
    <visual>
      <origin rpy="1.5707963267948966 0 0" xyz="0 0 0"/>
      <geometry>
        <cylinder length="0.055" radius="0.0575"/>
      </geometry>
      <material name="yellow"/>
    </visual>
    <collision>
      <origin rpy="1.5707963267948966 0 0" xyz="0 0 0"/>
      <geometry>
        <cylinder length="0.055" radius="0.0575"/>
      </geometry>
    </collision>
    <inertial>
      <origin rpy="1.5707963267948966 0 0" xyz="0 0 0"/>
      <mass value="0.3"/>
      <inertia ixx="0.00032359375" ixy="0" ixz="0" iyy="0.00032359375" iyz="0" izz="0.0004959375000000001"/>
    </inertial>
  </link>
  <joint name="left_f_wheel_joint" type="fixed">
    <parent link="base_link"/>
    <child link="left_f_wheel"/>
    <origin rpy="0 0 0" xyz="0.1075 -0.0975 0"/>
  </joint>
  <!-- Front Right Wheel (mirror of left) -->
  <link name="right_f_wheel">
    <!-- Same visual/collision/inertial as left wheel -->
    <visual>
      <origin rpy="1.5707963267948966 0 0" xyz="0 0 0"/>
      <geometry>
        <cylinder length="0.055" radius="0.0575"/>
      </geometry>
      <material name="yellow"/>
    </visual>
    <!-- ... other properties identical to left_f_wheel ... -->
  </link>
  <joint name="right_f_wheel_joint" type="fixed">
    <parent link="base_link"/>
    <child link="right_f_wheel"/>
    <origin rpy="0 0 0" xyz="0.1075 0.0975 0"/>
  </joint>
  <!-- Rear Wheels (same as front but negative x position) -->
  <link name="left_b_wheel">
    <!-- Identical to front wheels -->
  </link>
  <joint name="left_b_wheel_joint" type="fixed">
    <parent link="base_link"/>
    <child link="left_b_wheel"/>
    <origin rpy="0 0 0" xyz="-0.1075 -0.0975 0"/>
  </joint>
  <link name="right_b_wheel">
    <!-- Identical to front wheels -->
  </link>
  <joint name="right_b_wheel_joint" type="fixed">
    <parent link="base_link"/>
    <child link="right_b_wheel"/>
    <origin rpy="0 0 0" xyz="-0.1075 0.0975 0"/>
  </joint>
  <!-- Virtual drive joint for the single motor -->
  <link name="virtual_drive_link"/>
  <joint name="main_drive_joint" type="continuous">
    <parent link="base_link"/>
    <child link="virtual_drive_link"/>
    <axis xyz="0 1 0"/>
    <limit effort="100" velocity="10.0"/>
  </joint>
  <ros2_control name="robogardener" type="system">
    <joint name="main_drive_joint">
      <command_interface name="velocity"/>
      <state_interface name="position"/>
      <state_interface name="velocity"/>
    </joint>
  </ros2_control>
</robot>
